Workbook

Sheet Details
A2: Hello Welcome to HydroPipe ,
A3: Enter Details
A4: Project Name:
A5: Company Name:
A6: Client Name:
A7: Moblie Number:
A8: Email ID:
A10: Inputs for Design
A11: Design discharge (Q) | B11: 29.7 | C11: m3/s
A12: Total pipe length (L) | B12: 100 | C12: km
A13: Static head(Hs) | B13: 0 | C13: m
A15: Assumed Thickness (t) | B15: 25 | C15: mm
A16: Internal lining | B16: 0 | C16: mm
A17: External Guniting thickness | B17: 0 | C17: mm
A19: Type of Steel | B19: Fe-410
A20: Modulus of elasticity of pipe material (E) | B20: 2100000 | C20: Kg/cm2
A21: Density of lining mortar | B21: 0 | C21: Kg/cm3
A22: Modulus of elasticity of C.M. lining (Es) | B22: 357000 | C22: Kg/cm3
A24: Type of welding | B24: Field Welding
A26: Angle of uniformity spread load | B26: 180 | C26: Degrees
A27: Bedding reaction angle | B27: 30 | C27: Degrees
A28: Modulus of passive resistance of soil (e') | B28: 80 | C28: kg/cm2

Sheet Calculations
A1: Design of MS-Pipeline
A3: Parameter | B3: Unit | C3: Value | D3: Round Off Value | E3: Remarks
A4: Design discharge (Q) | B4: m3/s | C4: =Details!B11 -> 29.7 | D4: =ROUNDUP(1.1*C4,0) -> 33 | E4: 10% increase for design dicharge as factor of safety
A5: Total pipe length (L) | B5: km | C5: =Details!B12 -> 100
A6: Static head(Hs) | B6: m | C6: =Details!B13 -> 0
A8: Diameter Calculation
A9: Velocity (V) | B9: m/sec | C9: 2 | E9: As per CWC v<3m/sec and as per CPHEEO v<2.5 m/sec For raw water
A10: Area (A) | B10: m2 | C10: =D4/C9 -> 16.5
A11: Diameter (D) | B11: m | C11: =SQRT(C10*4/3.14) -> 4.5846601
A12: Maximum Diameter | B12: m | C12: 3.5 | E12: 3.5 m Diameter can easily be transported so economical
A13: No. of Pipes | C13: =ROUNDUP(C11/C12,0) -> 2
A14: Diameter of Each Pipe | B14: m | C14: =IF(C13>1,C12,_xlfn.XLOOKUP(C11,'Pipe Sizes'!A5:K5,'Pipe Sizes'!A5:K5,"No size Available",1)) -> 3.5
A16: Total Head-loss Calculation
A17: Frictional head Loss (Hf) | B17: m/km | C17: 0.77 | E17: As per CWC Section 5.3, a friction-loss range of 0.4–1.5 m per 1,000 m will generally be economical
A18: Dynamic Head (Hd) | E18: Not Considered in India
A19: Total Head Loss (H) | B19: m | C19: =C6+C17*C5 -> 77 | D19: =ROUNDUP(C19,-1) -> 80
A21: Velocity Check
A22: Area | B22: =C13*3.14*C14^2/4 -> 19.2325
A23: Velocity | B23: =D4/B22 -> 1.7158456 | E23: <2m/s
B24: =IF(B23<2,"OK","fail") -> OK | C24: =IF(B24="fail","Increase the Diameter of Pipe or Increase More No. of Pipe"," ")
A26: STRUCTURAL DESIGN FOR M.S. PIPE
A27: (A) Basic Data :
A28: Inner Diameter of Pipe(D) | B28: mm | C28: 2500
A29: Assumed Thickness (t) | B29: mm | C29: =Details!B15 -> 25
A30: Internal lining | B30: mm | C30: =Details!B16 -> 0 | E30: As per IS 1916 : 2018 Table 2
A31: External Guniting thickness | B31: mm | C31: =Details!B17 -> 0 | E31: As per IS 1916 : 2018 Table 2
A32: Diameter of Base Pipeline | B32: mm | C32: =C28+2*C29 -> 2550
A33: Outside diameter of pipe Including Guniting | B33: mm | C33: =C28+2*C29+2*C31 -> 2550
A34: Pressure on pipeline due to Working design | B34: m of water | C34: 225 | E34: As per IS 1916 : 2018 Section-3
A35: Pressure on the pipeline due to surge effect after providing surge protection system, if any | B35: m of water | C35: 123.7 | E35: Doubt
A36: Saturated density of filling (ϒs ) | B36: t/m3 | C36: 1.8
A37: Bedding angle | B37: Degrees | C37: 30 | E37: 25-30
A38: Trench width (BD) | B38: mm | C38: =2.5*C32 -> 6375 | E38: from Section 6 of IELRC.ORG - Manual on Sewerage and Sewage Treatment, 1993
A39: Degree of compaction as specified in trenches | B39: % | C39: 90
A40: Length of pipe | B40: mm | C40: =C5*1000 -> 100000
A42: (B) PROPERTIES OF MATERIAL :
A43: Type of Steel | C43: =Details!B19 -> Fe-410 | E43: AS per IS 2062 - 1962
A44: Yield Stress | B44: kg/cm2 | C44: =_xlfn.XLOOKUP(C43,'Grade of steel'!A4:A12,'Grade of steel'!D4:D12)*10 -> 2500
A45: Permissible compressive stress at 50% of Ys. for efficiency of welding Joint | B45: kg/cm2 | C45: =0.5*C44 -> 1250 | E45: Aussumed fos=2 for compression
A46: Permissible tensile stress at 60% of Ys. for efficiency of welding joint | B46: kg/cm2 | C46: =0.6*C44 -> 1500 | E46: Aussumed fos=1.67 for Tension
...

Sheet Pipe Sizes
A2: Data
A4: Available internal diameter (m)
A5: 0.5 | B5: 0.6 | C5: 0.8 | D5: 1 | E5: 1.2 | F5: 1.4 | G5: 1.6 | H5: 2 | I5: 2.5 | J5: 3 | K5: 3.5

Sheet Grade of steel
A2: AS per IS 2062 - 1962
A3: Grade (Fe-style) | B3: Original Grade | C3: Tensile Strength Rm, Min (MPa) | D3: Yield Stress <20 mm, Min (MPa)
A4: Fe-410 | B4: E 250 | C4: 410 | D4: 250
A5: Fe-430 | B5: E 275 | C5: 430 | D5: 275
A6: Fe-440 | B6: E 300 | C6: 440 | D6: 300
A7: Fe-490 | B7: E 350 | C7: 490 | D7: 350
A8: Fe-540 | B8: E 410 | C8: 540 | D8: 410
A9: Fe-570 | B9: E 450 | C9: 570 | D9: 450
A10: Fe-650 | B10: E 550 | C10: 650 | D10: 550
A11: Fe-730 | B11: E 600 | C11: 730 | D11: 600
A12: Fe-780 | B12: E 650 | C12: 780 | D12: 650

Sheet Load co-efficient Cd
A2: Table 6.3 of Manual on Sewer
A3: H/Bd | B3: Minimum, no cohesion | C3: Maximum ordinary sand | D3: Completely top soil | E3: Ordinary maximum clay | F3: Extreme maximum clay
A4: 0.5 | B4: 0.455 | C4: 0.461 | D4: 0.464 | E4: 0.469 | F4: 0.474
A5: 1 | B5: 0.83 | C5: 0.852 | D5: 0.864 | E5: 0.881 | F5: 0.898
A6: 1.5 | B6: 1.14 | C6: 1.183 | D6: 1.208 | E6: 1.242 | F6: 1.278
A7: 2 | B7: 1.395 | C7: 1.464 | D7: 1.504 | E7: 1.56 | F7: 1.618
A8: 2.5 | B8: 1.606 | C8: 1.702 | D8: 1.764 | E8: 1.838 | F8: 1.923
A9: 3 | B9: 1.78 | C9: 1.904 | D9: 1.978 | E9: 2.083 | F9: 2.196
A10: 3.5 | B10: 1.923 | C10: 2.075 | D10: 2.167 | E10: 2.298 | F10: 2.441
A11: 4 | B11: 2.041 | C11: 2.221 | D11: 2.329 | E11: 2.487 | F11: 2.66
A12: 4.5 | B12: 2.136 | C12: 2.344 | D12: 2.469 | E12: 2.65 | F12: 2.856
A13: 5 | B13: 2.219 | C13: 2.448 | D13: 2.59 | E13: 2.798 | F13: 3.032
A14: 5.5 | B14: 2.286 | C14: 2.537 | D14: 2.693 | E14: 2.926 | F14: 3.19
A15: 6 | B15: 2.34 | C15: 2.612 | D15: 2.782 | E15: 3.038 | F15: 3.331
... A28: 15 | B28: 2.591 | C28: 3.009 | D28: 3.296 | E28: 3.768 | F28: 4.378
A29: Very great | B29: 2.599 | C29: 3.03 | D29: 3.333 | E29: 3.846 | F29: 4.548

Sheet CWC and IWWA Tables
A1: Table 3.1: Co-efficient of bending moments and deflection of elastic ring under uniformly distributed load with load spread for 0 to 180 degree
A3: Load spread: | B3: Angle of spread θ (°) | C3: Kb (bottom bending) | D3: Kt (top bending) | E3: Ks (side bending) | F3: K0 (vertical deflection)
A4: 0 | B4: 0 | C4: 0.318 | D4: 0.318 | E4: 0.182 | F4: 0.137
B5: 30 | C5: 0.259 | D5: 0.318 | E5: 0.18 | F5: 0.135
B6: 60 | C6: 0.213 | D6: 0.312 | E6: 0.175 | F6: 0.13
B7: 90 | C7: 0.182 | D7: 0.302 | E7: 0.168 | F7: 0.122
B8: 120 | C8: 0.162 | D8: 0.299 | E8: 0.161 | F8: 0.116
B9: 150 | C9: 0.153 | D9: 0.295 | E9: 0.156 | F9: 0.111
B10: 180 | C10: 0.15 | D10: 0.294 | E10: 0.153 | F10: 0.11
A12: Load spread: | B12: Angle of spread θ (°) | C12: Kb (bottom bending) | D12: Kt (top bending) | E12: Ks (side bending) | F12: K0 (vertical deflection)
A13: 180 | B13: 0 | C13: 0.294 | D13: 0.15 | E13: 0.153 | F13: 0.11
B14: 30 | C14: 0.235 | D14: 0.148 | E14: 0.152 | F14: 0.108
B15: 60 | C15: 0.18 | D15: 0.143 | E15: 0.147 | F15: 0.103
B16: 90 | C16: 0.157 | D16: 0.137 | E16: 0.14 | F16: 0.096
B17: 120 | C17: 0.138 | D17: 0.131 | E17: 0.133 | F17: 0.089
B18: 150 | C18: 0.128 | D18: 0.126 | E18: 0.127 | F18: 0.085
B19: 180 | C19: 0.125 | D19: 0.125 | E19: 0.125 | F19: 0.083

Sheet Final Report
A1: Detailed Design Report
A4: Project Name: | B4: {=Details!B4:B8} -> 0
A5: Company Name: | B5: 0
A6: Client Name: | B6: 0
A7: Moblie Number: | B7: 0
A8: Email ID: | B8: 0
A10: Design of MS-Pipeline
A12: Parameter | B12: Unit | C12: Value | D12: Round Off Value
A13: Design discharge (Q) | B13: m3/s | C13: =Details!B11 -> 29.7 | D13: =ROUNDUP(1.1*C13,0) -> 33
A14: Total pipe length (L) | B14: km | C14: =Details!B12 -> 100
A15: Static head(Hs) | B15: m | C15: =Details!B13 -> 0
A17: Diameter Calculation
A18: Velocity (V) | B18: m/sec | C18: 2
A19: Area (A) | B19: m2 | C19: =D13/C18 -> 16.5
A20: Diameter (D) | B20: m | C20: =SQRT(C19*4/3.14) -> 4.5846601
A21: Maximum Diameter | B21: m | C21: 3.5
A22: No. of Pipes | C22: =ROUNDUP(C20/C21,0) -> 2
A23: Diameter of Each Pipe | B23: m | C23: =IF(C22>1,C21,_xlfn.XLOOKUP(C20,'Pipe Sizes'!A5:K5,'Pipe Sizes'!A5:K5,"No size Available",1)) -> 3.5
A25: Total Head-loss Calculation
A26: Frictional head Loss (Hf) | B26: m/km | C26: 0.77
A27: Dynamic Head (Hd)
A28: Total Head Loss (H) | B28: m | C28: =C15+C26*C14 -> 77 | D28: =ROUNDUP(C28,-1) -> 80
A30: Velocity Check
A31: Area | B31: =C22*3.14*C23^2/4 -> 19.2325
A32: Velocity | B32: =D13/B31 -> 1.7158456
B33: =IF(B32<2,"OK","fail") -> OK | C33: =IF(B33="fail","Increase the Diameter of Pipe or Increase More No. of Pipe"," ")
A35: STRUCTURAL DESIGN FOR M.S. PIPE
A36: (A) Basic Data :
A37: Inner Diameter of Pipe(D) | B37: mm | C37: 2500
A38: Assumed Thickness (t) | B38: mm | C38: =Details!B15 -> 25
A39: Internal lining | B39: mm | C39: =Details!B16 -> 0
A40: External Guniting thickness | B40: mm | C40: =Details!B17 -> 0
A41: Diameter of Base Pipeline | B41: mm | C41: =C37+2*C38 -> 2550
A42: Outside diameter of pipe Including Guniting | B42: mm | C42: =C37+2*C38+2*C40 -> 2550
A43: Pressure on pipeline due to Working design | B43: m of water | C43: 225
A44: Pressure on the pipeline due to surge effect after providing surge protection system, if any | B44: m of water | C44: 123.7
A45: Saturated density of filling (ϒs ) | B45: t/m3 | C45: 1.8
A46: Bedding angle | B46: Degrees | C46: 30
A47: Trench width (BD) | B47: mm | C47: =2.5*C41 -> 6375
A48: Degree of compaction as specified in trenches | B48: % | C48: 90
...
